Workbook

Sheet 1ST TERM ACCOUNT
A1: LAST NAME | B1: FIRST NAME | C1: CLASS | D1: DISCOUNT | E1: AD-FORM | F1: FULL TUITION | G1: PTA/EXAM | H1: REPORT CARD | I1: PRACTICALS | J1: AD_FORM | K1: TUITION | L1: PTA&EXAM | M1: REPORT_CARD | N1: PRACTICAL | O1: TEXTBOOKS | P1: NB & STAT | Q1: UNIFORM | R1: HOODY | S1: SPORTSWEAR | T1: AFTERSCHOOL | U1: EXCURSION | V1: EXTERNAL EXAMINATION | W1: GRADUATION/ SPORTS/PARTY | X1: HOLIDAY LESSON | Y1: OUTSTANDING | Z1: TOTAL FEE | AA1: TOTAL PAID | AB1: BALANCE | AC1: LESSON FEE PRY | AD1: LESSON FEE SEC | AE1: PARTY FEE REMIT | AF1: COMMENT
A2: ABDULAZEEZ | B2: ABDULLAH | C2: NURSERY 1 | D2: 0.25 | E2: 0 | F2: 26000 | G2: 4000 | H2: 0 | I2: 0 | J2: =(1-$D2)*E2 -> 0 | K2: =(1-$D2)*F2 -> 19500 | L2: =G2 -> 4000 | M2: =(1-$D2)*H2 -> 0 | N2: =(1-$D2)*I2 -> 0 | O2: 13380 | P2: 7550 | Q2: 0 | R2: 0 | S2: 0 | T2: 6000 | U2: 0 | V2: 0 | W2: 0 | X2: 0 | Y2: 750 | Z2: =SUM(J2:Y2) -> 51180 | AA2: 51180 | AB2: =Z2-AA2 -> 0 | AC2: =IF(AND($T2=6000, ($T2+$W2-$AB2)>=6000),T2,"") -> 6000 | AD2: =IF(AND($T2=8000, ($T2+$W2-$AB2)>=8000),T2,"") | AE2: =IF(($T2+$W2-$AB2)>=$T2+8000,W2,"")
A3: ABDULAZEEZ | B3: FIRDAOS | C3: PRIMARY 2 | D3: 0.25 | E3: 0 | F3: 28000 | G3: 4000 | H3: 0 | I3: 5000 | J3: =(1-$D3)*E3 -> 0 | K3: =(1-$D3)*F3 -> 21000 | L3: =G3 -> 4000 | M3: =(1-$D3)*H3 -> 0 | N3: =(1-$D3)*I3 -> 3750 | O3: 26150 | P3: 11330 | Q3: 0 | R3: 0 | S3: 0 | T3: 6000 | U3: 0 | V3: 0 | W3: 0 | X3: 0 | Y3: 125 | Z3: =SUM(J3:Y3) -> 72355 | AA3: 30000 | AB3: =Z3-AA3 -> 42355 | AC3: =IF(AND($T3=6000, ($T3+$W3-$AB3)>=6000),T3,"") | AD3: =IF(AND($T3=8000, ($T3+$W3-$AB3)>=8000),T3,"") | AE3: =IF(($T3+$W3-$AB3)>=$T3+8000,W3,"")
A4: ABDULLATEEF | B4: MUHAMMED | C4: SENIOR SECONDARY SCHOOL 2 | D4: 0 | E4: 0 | F4: 40000 | G4: 5000 | H4: 2000 | I4: 8000 | J4: =(1-$D4)*E4 -> 0 | K4: =(1-$D4)*F4 -> 40000 | L4: =G4 -> 5000 | M4: =(1-$D4)*H4 -> 2000 | N4: =(1-$D4)*I4 -> 8000 | O4: =11880-6180 -> 5700 | P4: =14330-11400 -> 2930 | Q4: 0 | R4: 0 | S4: 0 | T4: 0 | U4: 0 | V4: 0 | W4: 0 | X4: 0 | Y4: 0 | Z4: =SUM(J4:Y4) -> 63630 | AA4: 40000 | AB4: =Z4-AA4 -> 23630 | AC4: =IF(AND($T4=6000, ($T4+$W4-$AB4)>=6000),T4,"") | AD4: =IF(AND($T4=8000, ($T4+$W4-$AB4)>=8000),T4,"") | AE4: =IF(($T4+$W4-$AB4)>=$T4+8000,W4,"")
A5: ABIDOYE | B5: AL-AMEER OLUWAJOMILOJU | C5: NURSERY 2 | D5: 0.25 | E5: 0 | F5: 26000 | G5: 4000 | H5: 0 | I5: 0 | J5: =(1-$D5)*E5 -> 0 | K5: =(1-$D5)*F5 -> 19500 | L5: =G5 -> 4000 | M5: =(1-$D5)*H5 -> 0 | N5: =(1-$D5)*I5 -> 0 | O5: 24930 | P5: 10730 | Q5: 0 | R5: 0 | S5: 0 | T5: 0 | U5: 0 | V5: 0 | W5: 0 | X5: 0 | Y5: 0 | Z5: =SUM(J5:Y5) -> 59160 | AA5: 0 | AB5: =Z5-AA5 -> 59160 | AC5: =IF(AND($T5=6000, ($T5+$W5-$AB5)>=6000),T5,"") | AD5: =IF(AND($T5=8000, ($T5+$W5-$AB5)>=8000),T5,"") | AE5: =IF(($T5+$W5-$AB5)>=$T5+8000,W5,"")
A6: ABIDOYE | B6: SULTAN ORODE | C6: PLAYGROUP 2 | D6: 0.25 | E6: 0 | F6: 26000 | G6: 4000 | H6: 1000 | I6: 0 | J6: =(1-$D6)*E6 -> 0 | K6: =(1-$D6)*F6 -> 19500 | L6: =G6 -> 4000 | M6: =(1-$D6)*H6 -> 750 | N6: =(1-$D6)*I6 -> 0 | O6: 12480 | P6: 7550 | Q6: 0 | R6: 0 | S6: 0 | T6: 0 | U6: 0 | V6: 0 | W6: 0 | X6: 0 | Y6: 0 | Z6: =SUM(J6:Y6) -> 44280 | AA6: 0 | AB6: =Z6-AA6 -> 44280 | AC6: =IF(AND($T6=6000, ($T6+$W6-$AB6)>=6000),T6,"") | AD6: =IF(AND($T6=8000, ($T6+$W6-$AB6)>=8000),T6,"") | AE6: =IF(($T6+$W6-$AB6)>=$T6+8000,W6,"")
A7: ABIODUN | B7: CHARIS ADEEWA | C7: NURSERY 1 | D7: 0.25 | E7: 0 | F7: 26000 | G7: 4000 | H7: 0 | I7: 0 | J7: =(1-$D7)*E7 -> 0 | K7: =(1-$D7)*F7 -> 19500 | L7: =G7 -> 4000 | M7: =(1-$D7)*H7 -> 0 | N7: =(1-$D7)*I7 -> 0 | O7: 13380 | P7: 7550 | Q7: 0 | R7: 0 | S7: 0 | T7: 0 | U7: 0 | V7: 0 | W7: 0 | X7: 0 | Y7: 0 | Z7: =SUM(J7:Y7) -> 44430 | AA7: 20000 | AB7: =Z7-AA7 -> 24430 | AC7: =IF(AND($T7=6000, ($T7+$W7-$AB7)>=6000),T7,"") | AD7: =IF(AND($T7=8000, ($T7+$W7-$AB7)>=8000),T7,"") | AE7: =IF(($T7+$W7-$AB7)>=$T7+8000,W7,"")
A8: ABIODUN | B8: DANIEL OBANIJESU | C8: PLAYGROUP 2 | D8: 0.25 | E8: 0 | F8: 26000 | G8: 4000 | H8: 1000 | I8: 0 | J8: =(1-$D8)*E8 -> 0 | K8: =(1-$D8)*F8 -> 19500 | L8: =G8 -> 4000 | M8: =(1-$D8)*H8 -> 750 | N8: =(1-$D8)*I8 -> 0 | O8: 12480 | P8: 7550 | Q8: 0 | R8: 0 | S8: 0 | T8: 6000 | U8: 0 | V8: 0 | W8: 0 | X8: 0 | Y8: -90 | Z8: =SUM(J8:Y8) -> 50190 | AA8: 30000 | AB8: =Z8-AA8 -> 20190 | AC8: =IF(AND($T8=6000, ($T8+$W8-$AB8)>=6000),T8,"") | AD8: =IF(AND($T8=8000, ($T8+$W8-$AB8)>=8000),T8,"") | AE8: =IF(($T8+$W8-$AB8)>=$T8+8000,W8,"")
A9: ABIODUN | B9: SHARON ADELEWA | C9: PLAYGROUP 2 | D9: 0.25 | E9: 0 | F9: 26000 | G9: 4000 | H9: 1000 | I9: 0 | J9: =(1-$D9)*E9 -> 0 | K9: =(1-$D9)*F9 -> 19500 | L9: =G9 -> 4000 | M9: =(1-$D9)*H9 -> 750 | N9: =(1-$D9)*I9 -> 0 | O9: 12480 | P9: 7550 | Q9: 0 | R9: 0 | S9: 0 | T9: 0 | U9: 0 | V9: 0 | W9: 0 | X9: 0 | Y9: 0 | Z9: =SUM(J9:Y9) -> 44280 | AA9: 20000 | AB9: =Z9-AA9 -> 24280 | AC9: =IF(AND($T9=6000, ($T9+$W9-$AB9)>=6000),T9,"") | AD9: =IF(AND($T9=8000, ($T9+$W9-$AB9)>=8000),T9,"") | AE9: =IF(($T9+$W9-$AB9)>=$T9+8000,W9,"")
A10: ABIODUN | B10: IVANA ADESEWA | C10: PRIMARY 3 | D10: 0.25 | E10: 0 | F10: 28000 | G10: 4000 | H10: 0 | I10: 5000 | J10: =(1-$D10)*E10 -> 0 | K10: =(1-$D10)*F10 -> 21000 | L10: =G10 -> 4000 | M10: =(1-$D10)*H10 -> 0 | N10: =(1-$D10)*I10 -> 3750 | O10: 27310 | P10: 13230 | Q10: 0 | R10: 0 | S10: 0 | T10: 0 | U10: 0 | V10: 0 | W10: 0 | X10: 0 | Y10: 0 | Z10: =SUM(J10:Y10) -> 69290 | AA10: 20000 | AB10: =Z10-AA10 -> 49290 | AC10: =IF(AND($T10=6000, ($T10+$W10-$AB10)>=6000),T10,"") | AD10: =IF(AND($T10=8000, ($T10+$W10-$AB10)>=8000),T10,"") | AE10: =IF(($T10+$W10-$AB10)>=$T10+8000,W10,"")
A11: ADEBOWALE | B11: MARTIN | C11: PRIMARY 3 | D11: 0 | E11: 2000 | F11: 28000 | G11: 4000 | H11: 2500 | I11: 5000 | J11: =(1-$D11)*E11 -> 2000 | K11: =(1-$D11)*F11 -> 28000 | L11: =G11 -> 4000 | M11: =(1-$D11)*H11 -> 2500 | N11: =(1-$D11)*I11 -> 5000 | O11: 27310 | P11: 13230 | Q11: 16000 | R11: 8000 | S11: 7000 | T11: 6000 | U11: 0 | V11: 0 | W11: 0 | X11: 0 | Y11: 0 | Z11: =SUM(J11:Y11) -> 119040 | AA11: 119000 | AB11: =Z11-AA11 -> 40 | AC11: =IF(AND($T11=6000, ($T11+$W11-$AB11)>=6000),T11,"") | AD11: =IF(AND($T11=8000, ($T11+$W11-$AB11)>=8000),T11,"") | AE11: =IF(($T11+$W11-$AB11)>=$T11+8000,W11,"")
A12: ADEBOYE | B12: ELIZABETH | C12: JUNIOR SECONDARY SCHOOL 2 | D12: 0.25 | E12: 0 | F12: 33000 | G12: 5000 | H12: 2000 | I12: 6000 | J12: =(1-$D12)*E12 -> 0 | K12: =(1-$D12)*F12 -> 24750 | L12: =G12 -> 5000 | M12: =(1-$D12)*H12 -> 1500 | N12: =(1-$D12)*I12 -> 4500 | O12: =19500-11160 -> 8340 | P12: =14330-5700 -> 8630 | Q12: 0 | R12: 0 | S12: 0 | T12: 8000 | U12: 0 | V12: 0 | W12: 0 | X12: 0 | Y12: 750 | Z12: =SUM(J12:Y12) -> 61470 | AA12: 35000 | AB12: =Z12-AA12 -> 26470 | AC12: =IF(AND($T12=6000, ($T12+$W12-$AB12)>=6000),T12,"") | AD12: =IF(AND($T12=8000, ($T12+$W12-$AB12)>=8000),T12,"") | AE12: =IF(($T12+$W12-$AB12)>=$T12+8000,W12,"")
A13: ADEBOYE | B13: ENIOLA ESTHER | C13: SENIOR SECONDARY SCHOOL 1 | D13: 0.25 | E13: 0 | F13: 40000 | G13: 5000 | H13: 2000 | I13: 8000 | J13: =(1-$D13)*E13 -> 0 | K13: =(1-$D13)*F13 -> 30000 | L13: =G13 -> 5000 | M13: =(1-$D13)*H13 -> 1500 | N13: =(1-$D13)*I13 -> 6000 | O13: 0 | P13: =14330-5700 -> 8630 | Q13: 20000 | R13: 0 | S13: 0 | T13: 0 | U13: 0 | V13: 0 | W13: 0 | X13: 0 | Y13: 540 | Z13: =SUM(J13:Y13) -> 71670 | AA13: 35000 | AB13: =Z13-AA13 -> 36670 | AC13: =IF(AND($T13=6000, ($T13+$W13-$AB13)>=6000),T13,"") | AD13: =IF(AND($T13=8000, ($T13+$W13-$AB13)>=8000),T13,"") | AE13: =IF(($T13+$W13-$AB13)>=$T13+8000,W13,"")
A14: ADEBUNMI | B14: ADEYEMI | C14: NURSERY 2 | D14: 0.5 | E14: 0 | F14: 26000 | G14: 4000 | H14: 0 | I14: 0 | J14: =(1-$D14)*E14 -> 0 | K14: =(1-$D14)*F14 -> 13000 | L14: =G14 -> 4000 | M14: =(1-$D14)*H14 -> 0 | N14: =(1-$D14)*I14 -> 0 | O14: 24930 | P14: 10730 | Q14: 0 | R14: 0 | S14: 0 | T14: 0 | U14: 0 | V14: 0 | W14: 0 | X14: 0 | Y14: 0 | Z14: =SUM(J14:Y14) -> 52660 | AA14: 52660 | AB14: =Z14-AA14 -> 0 | AC14: =IF(AND($T14=6000, ($T14+$W14-$AB14)>=6000),T14,"") | AD14: =IF(AND($T14=8000, ($T14+$W14-$AB14)>=8000),T14,"") | AE14: =IF(($T14+$W14-$AB14)>=$T14+8000,W14,"")
A15: ADEBUNMI | B15: ADEOLUWA | C15: PRIMARY 3 | D15: 0.5 | E15: 0 | F15: 28000 | G15: 4000 | H15: 0 | I15: 5000 | J15: =(1-$D15)*E15 -> 0 | K15: =(1-$D15)*F15 -> 14000 | L15: =G15 -> 4000 | M15: =(1-$D15)*H15 -> 0 | N15: =(1-$D15)*I15 -> 2500 | O15: 27310 | P15: 13230 | Q15: 0 | R15: 0 | S15: 0 | T15: 0 | U15: 0 | V15: 0 | W15: 0 | X15: 0 | Y15: -530 | Z15: =SUM(J15:Y15) -> 60510 | AA15: 61090 | AB15: =Z15-AA15 -> -580 | AC15: =IF(AND($T15=6000, ($T15+$W15-$AB15)>=6000),T15,"") | AD15: =IF(AND($T15=8000, ($T15+$W15-$AB15)>=8000),T15,"") | AE15: =IF(($T15+$W15-$AB15)>=$T15+8000,W15,"")
A16: ADEDAMOLA | B16: IREMIDE | C16: PLAYGROUP 1 | D16: 0.05 | E16: 0 | F16: 26000 | G16: 4000 | H16: 1000 | I16: 0 | J16: =(1-$D16)*E16 -> 0 | K16: =(1-$D16)*F16 -> 24700 | L16: =G16 -> 4000 | M16: =(1-$D16)*H16 -> 950 | N16: =(1-$D16)*I16 -> 0 | O16: 6840 | P16: 5300 | Q16: 0 | R16: 0 | S16: 0 | T16: 0 | U16: 0 | V16: 0 | W16: 0 | X16: 0 | Y16: -1000 | Z16: =SUM(J16:Y16) -> 40790 | AA16: 42140 | AB16: =Z16-AA16 -> -1350 | AC16: =IF(AND($T16=6000, ($T16+$W16-$AB16)>=6000),T16,"") | AD16: =IF(AND($T16=8000, ($T16+$W16-$AB16)>=8000),T16,"") | AE16: =IF(($T16+$W16-$AB16)>=$T16+8000,W16,"") | AF16: BONUS
A17: ADEDAYO | B17: DORCAS ADEMIDE | C17: NURSERY 2 | D17: 0.25 | E17: 0 | F17: 26000 | G17: 4000 | H17: 0 | I17: 0 | J17: =(1-$D17)*E17 -> 0 | K17: =(1-$D17)*F17 -> 19500 | L17: =G17 -> 4000 | M17: =(1-$D17)*H17 -> 0 | N17: =(1-$D17)*I17 -> 0 | O17: 24930 | P17: 10730 | Q17: 0 | R17: 0 | S17: 0 | T17: 0 | U17: 0 | V17: 0 | W17: 0 | X17: 0 | Y17: 0 | Z17: =SUM(J17:Y17) -> 59160 | AA17: 40000 | AB17: =Z17-AA17 -> 19160 | AC17: =IF(AND($T17=6000, ($T17+$W17-$AB17)>=6000),T17,"") | AD17: =IF(AND($T17=8000, ($T17+$W17-$AB17)>=8000),T17,"") | AE17: =IF(($T17+$W17-$AB17)>=$T17+8000,W17,"")
A18: ADEDAYO | B18: DEBORAH ADESIRE | C18: PRIMARY 3 | D18: 0.25 | E18: 0 | F18: 28000 | G18: 4000 | H18: 0 | I18: 5000 | J18: =(1-$D18)*E18 -> 0 | K18: =(1-$D18)*F18 -> 21000 | L18: =G18 -> 4000 | M18: =(1-$D18)*H18 -> 0 | N18: =(1-$D18)*I18 -> 3750 | O18: 27310 | P18: 10740 | Q18: 0 | R18: 0 | S18: 0 | T18: 0 | U18: 0 | V18: 0 | W18: 0 | X18: 0 | Y18: 0 | Z18: =SUM(J18:Y18) -> 66800 | AA18: 40000 | AB18: =Z18-AA18 -> 26800 | AC18: =IF(AND($T18=6000, ($T18+$W18-$AB18)>=6000),T18,"") | AD18: =IF(AND($T18=8000, ($T18+$W18-$AB18)>=8000),T18,"") | AE18: =IF(($T18+$W18-$AB18)>=$T18+8000,W18,"")
A19: ADEDINI | B19: MARY OLUWATOFUNMI | C19: SENIOR SECONDARY SCHOOL 1 | D19: 0 | E19: 3000 | F19: 40000 | G19: 5000 | H19: 2000 | I19: 8000 | J19: =(1-$D19)*E19 -> 3000 | K19: =(1-$D19)*F19 -> 40000 | L19: =G19 -> 5000 | M19: =(1-$D19)*H19 -> 2000 | N19: =(1-$D19)*I19 -> 8000 | O19: 11880 | P19: 14330 | Q19: 20000 | R19: 8000 | S19: 8000 | T19: 0 | U19: 0 | V19: 0 | W19: 0 | X19: 0 | Y19: 0 | Z19: =SUM(J19:Y19) -> 120210 | AA19: 120210 | AB19: =Z19-AA19 -> 0 | AC19: =IF(AND($T19=6000, ($T19+$W19-$AB19)>=6000),T19,"") | AD19: =IF(AND($T19=8000, ($T19+$W19-$AB19)>=8000),T19,"") | AE19: =IF(($T19+$W19-$AB19)>=$T19+8000,W19,"")
A20: ADEDOJA | B20: FAITH MORAYOOLUWA | C20: PLAYGROUP 2 | D20: 0.3 | E20: 0 | F20: 26000 | G20: 4000 | H20: 1000 | I20: 0 | J20: =(1-$D20)*E20 -> 0 | K20: =(1-$D20)*F20 -> 18200 | L20: =G20 -> 4000 | M20: =(1-$D20)*H20 -> 700 | N20: =(1-$D20)*I20 -> 0 | O20: 12480 | P20: 7550 | Q20: 0 | R20: 0 | S20: 0 | T20: 6000 | U20: 0 | V20: 0 | W20: 0 | X20: 0 | Y20: 0 | Z20: =SUM(J20:Y20) -> 48930 | AA20: =42930+8765 -> 51695 | AB20: =Z20-AA20 -> -2765 | AC20: =IF(AND($T20=6000, ($T20+$W20-$AB20)>=6000),T20,"") -> 6000 | AD20: =IF(AND($T20=8000, ($T20+$W20-$AB20)>=8000),T20,"") | AE20: =IF(($T20+$W20-$AB20)>=$T20+8000,W20,"") | AF20: BONUS
A21: ADEDOJA | B21: MOJEREOLUWA PROSPER | C21: PRIMARY 1 | D21: 0.3 | E21: 0 | F21: 28000 | G21: 4000 | H21: 2500 | I21: 5000 | J21: =(1-$D21)*E21 -> 0 | K21: =(1-$D21)*F21 -> 19600 | L21: =G21 -> 4000 | M21: =(1-$D21)*H21 -> 1750 | N21: =(1-$D21)*I21 -> 3500 | O21: 25970 | P21: 11330 | Q21: 0 | R21: 0 | S21: 0 | T21: 6000 | U21: 0 | V21: 0 | W21: 0 | X21: 0 | Y21: 0 | Z21: =SUM(J21:Y21) -> 72150 | AA21: 72150 | AB21: =Z21-AA21 -> 0 | AC21: =IF(AND($T21=6000, ($T21+$W21-$AB21)>=6000),T21,"") -> 6000 | AD21: =IF(AND($T21=8000, ($T21+$W21-$AB21)>=8000),T21,"") | AE21: =IF(($T21+$W21-$AB21)>=$T21+8000,W21,"") | AF21: BONUS
A22: ADEDOJA | B22: PRAISE | C22: PRIMARY 5 | D22: 0.25 | E22: 0 | F22: 28000 | G22: 4000 | H22: 0 | I22: 5000 | J22: =(1-$D22)*E22 -> 0 | K22: =(1-$D22)*F22 -> 21000 | L22: =G22 -> 4000 | M22: =(1-$D22)*H22 -> 0 | N22: =(1-$D22)*I22 -> 3750 | O22: 28790 | P22: 13230 | Q22: 0 | R22: 0 | S22: 0 | T22: 6000 | U22: 0 | V22: 0 | W22: 0 | X22: 0 | Y22: 0 | Z22: =SUM(J22:Y22) -> 76770 | AA22: 76770 | AB22: =Z22-AA22 -> 0 | AC22: =IF(AND($T22=6000, ($T22+$W22-$AB22)>=6000),T22,"") -> 6000 | AD22: =IF(AND($T22=8000, ($T22+$W22-$AB22)>=8000),T22,"") | AE22: =IF(($T22+$W22-$AB22)>=$T22+8000,W22,"")
A23: ADEKUNLE | B23: MUMINAT ADEBOLA | C23: JUNIOR SECONDARY SCHOOL 3 | D23: 0.5 | E23: 0 | F23: 33000 | G23: 5000 | H23: 2000 | I23: 6000 | J23: =(1-$D23)*E23 -> 0 | K23: =(1-$D23)*F23 -> 16500 | L23: =G23 -> 5000 | M23: =(1-$D23)*H23 -> 1000 | N23: =(1-$D23)*I23 -> 3000 | O23: 22400 | P23: =14330-5700 -> 8630 | Q23: 0 | R23: 0 | S23: 0 | T23: 8000 | U23: 0 | V23: 0 | W23: 0 | X23: 0 | Y23: 0 | Z23: =SUM(J23:Y23) -> 64530 | AA23: 20000 | AB23: =Z23-AA23 -> 44530 | AC23: =IF(AND($T23=6000, ($T23+$W23-$AB23)>=6000),T23,"") | AD23: =IF(AND($T23=8000, ($T23+$W23-$AB23)>=8000),T23,"") | AE23: =IF(($T23+$W23-$AB23)>=$T23+8000,W23,"")
A24: ADELOYE | B24: PROSPER | C24: JUNIOR SECONDARY SCHOOL 2 | D24: 0.3 | E24: 0 | F24: 33000 | G24: 5000 | H24: 2000 | I24: 6000 | J24: =(1-$D24)*E24 -> 0 | K24: =(1-$D24)*F24 -> 23100 | L24: =G24 -> 5000 | M24: =(1-$D24)*H24 -> 1400 | N24: =(1-$D24)*I24 -> 4200 | O24: 19500 | P24: 14330 | Q24: 0 | R24: 0 | S24: 0 | T24: 0 | U24: 0 | V24: 0 | W24: 0 | X24: 0 | Y24: 0 | Z24: =SUM(J24:Y24) -> 67530 | AA24: 0 | AB24: =Z24-AA24 -> 67530 | AC24: =IF(AND($T24=6000, ($T24+$W24-$AB24)>=6000),T24,"") | AD24: =IF(AND($T24=8000, ($T24+$W24-$AB24)>=8000),T24,"") | AE24: =IF(($T24+$W24-$AB24)>=$T24+8000,W24,"")
A25: ADELOYE | B25: DANIEL | C25: PRIMARY 2 | D25: 0.25 | E25: 0 | F25: 28000 | G25: 4000 | H25: 0 | I25: 5000 | J25: =(1-$D25)*E25 -> 0 | K25: =(1-$D25)*F25 -> 21000 | L25: =G25 -> 4000 | M25: =(1-$D25)*H25 -> 0 | N25: =(1-$D25)*I25 -> 3750 | O25: 26150 | P25: 11330 | Q25: 0 | R25: 0 | S25: 0 | T25: 0 | U25: 0 | V25: 0 | W25: 0 | X25: 0 | Y25: 0 | Z25: =SUM(J25:Y25) -> 66230 | AA25: 0 | AB25: =Z25-AA25 -> 66230 | AC25: =IF(AND($T25=6000, ($T25+$W25-$AB25)>=6000),T25,"") | AD25: =IF(AND($T25=8000, ($T25+$W25-$AB25)>=8000),T25,"") | AE25: =IF(($T25+$W25-$AB25)>=$T25+8000,W25,"")
A26: ADELOYE | B26: EMMANUEL | C26: PRIMARY 2 | D26: 0.25 | E26: 0 | F26: 28000 | G26: 4000 | H26: 0 | I26: 5000 | J26: =(1-$D26)*E26 -> 0 | K26: =(1-$D26)*F26 -> 21000 | L26: =G26 -> 4000 | M26: =(1-$D26)*H26 -> 0 | N26: =(1-$D26)*I26 -> 3750 | O26: 26150 | P26: 11330 | Q26: 0 | R26: 0 | S26: 0 | T26: 0 | U26: 0 | V26: 0 | W26: 0 | X26: 0 | Y26: 0 | Z26: =SUM(J26:Y26) -> 66230 | AA26: 0 | AB26: =Z26-AA26 -> 66230 | AC26: =IF(AND($T26=6000, ($T26+$W26-$AB26)>=6000),T26,"") | AD26: =IF(AND($T26=8000, ($T26+$W26-$AB26)>=8000),T26,"") | AE26: =IF(($T26+$W26-$AB26)>=$T26+8000,W26,"")
A27: ADENIYI | B27: SAMUEL DEMILADE | C27: JUNIOR SECONDARY SCHOOL 2 | D27: 0 | E27: 0 | F27: 33000 | G27: 5000 | H27: 2000 | I27: 6000 | J27: =(1-$D27)*E27 -> 0 | K27: =(1-$D27)*F27 -> 33000 | L27: =G27 -> 5000 | M27: =(1-$D27)*H27 -> 2000 | N27: =(1-$D27)*I27 -> 6000 | O27: 19500 | P27: 14330 | Q27: 0 | R27: 0 | S27: 0 | T27: 0 | U27: 0 | V27: 0 | W27: 0 | X27: 0 | Y27: 0 | Z27: =SUM(J27:Y27) -> 79830 | AA27: 60000 | AB27: =Z27-AA27 -> 19830 | AC27: =IF(AND($T27=6000, ($T27+$W27-$AB27)>=6000),T27,"") | AD27: =IF(AND($T27=8000, ($T27+$W27-$AB27)>=8000),T27,"") | AE27: =IF(($T27+$W27-$AB27)>=$T27+8000,W27,"")
A28: ADENIYI | B28: HERITAGE ADEDOYIN | C28: JUNIOR SECONDARY SCHOOL 3 | D28: 0.55 | E28: 0 | F28: 33000 | G28: 5000 | H28: 2000 | I28: 6000 | J28: =(1-$D28)*E28 -> 0 | K28: =(1-$D28)*F28 -> 14850 | L28: =G28 -> 5000 | M28: =(1-$D28)*H28 -> 900 | N28: =(1-$D28)*I28 -> 2700 | O28: 22400 | P28: 14330 | Q28: 0 | R28: 0 | S28: 0 | T28: 0 | U28: 0 | V28: 0 | W28: 0 | X28: 0 | Y28: 0 | Z28: =SUM(J28:Y28) -> 60180 | AA28: 62230 | AB28: =Z28-AA28 -> -2050 | AC28: =IF(AND($T28=6000, ($T28+$W28-$AB28)>=6000),T28,"") | AD28: =IF(AND($T28=8000, ($T28+$W28-$AB28)>=8000),T28,"") | AE28: =IF(($T28+$W28-$AB28)>=$T28+8000,W28,"") | AF28: BONUS
A29: ADENIYI | B29: ABDULQUDUS | C29: PLAYGROUP 2 | D29: 0 | E29: 0 | F29: 26000 | G29: 4000 | H29: 1000 | I29: 0 | J29: =(1-$D29)*E29 -> 0 | K29: =(1-$D29)*F29 -> 26000 | L29: =G29 -> 4000 | M29: =(1-$D29)*H29 -> 1000 | N29: =(1-$D29)*I29 -> 0 | O29: 12480 | P29: 7550 | Q29: 0 | R29: 0 | S29: 0 | T29: 0 | U29: 0 | V29: 0 | W29: 0 | X29: 0 | Y29: -400 | Z29: =SUM(J29:Y29) -> 50630 | AA29: 0 | AB29: =Z29-AA29 -> 50630 | AC29: =IF(AND($T29=6000, ($T29+$W29-$AB29)>=6000),T29,"") | AD29: =IF(AND($T29=8000, ($T29+$W29-$AB29)>=8000),T29,"") | AE29: =IF(($T29+$W29-$AB29)>=$T29+8000,W29,"")
A30: ADEYANJU | B30: HASBULLAH OKIKIOLA | C30: PLAYGROUP 1 | D30: 0 | E30: 0 | F30: 26000 | G30: 4000 | H30: 1000 | I30: 0 | J30: =(1-$D30)*E30 -> 0 | K30: =(1-$D30)*F30 -> 26000 | L30: =G30 -> 4000 | M30: =(1-$D30)*H30 -> 1000 | N30: =(1-$D30)*I30 -> 0 | O30: 6840 | P30: 5300 | Q30: 16000 | R30: 0 | S30: 0 | T30: 0 | U30: 0 | V30: 0 | W30: 0 | X30: 0 | Y30: 0 | Z30: =SUM(J30:Y30) -> 59140 | AA30: 43140 | AB30: =Z30-AA30 -> 16000 | AC30: =IF(AND($T30=6000, ($T30+$W30-$AB30)>=6000),T30,"") | AD30: =IF(AND($T30=8000, ($T30+$W30-$AB30)>=8000),T30,"") | AE30: =IF(($T30+$W30-$AB30)>=$T30+8000,W30,"")
A31: ADEYEMI | B31: MODADEOBA GBOLAHAN | C31: PLAYGROUP 2 | D31: 0 | E31: 0 | F31: 26000 | G31: 4000 | H31: 1000 | I31: 0 | J31: =(1-$D31)*E31 -> 0 | K31: =(1-$D31)*F31 -> 26000 | L31: =G31 -> 4000 | M31: =(1-$D31)*H31 -> 1000 | N31: =(1-$D31)*I31 -> 0 | O31: 12480 | P31: 7550 | Q31: 0 | R31: 0 | S31: 0 | T31: 0 | U31: 0 | V31: 0 | W31: 0 | X31: 0 | Y31: 11000 | Z31: =SUM(J31:Y31) -> 62030 | AA31: 0 | AB31: =Z31-AA31 -> 62030 | AC31: =IF(AND($T31=6000, ($T31+$W31-$AB31)>=6000),T31,"") | AD31: =IF(AND($T31=8000, ($T31+$W31-$AB31)>=8000),T31,"") | AE31: =IF(($T31+$W31-$AB31)>=$T31+8000,W31,"")
A32: ADEYEMI | B32: ADETOLA PRINCESS | C32: SENIOR SECONDARY SCHOOL 2 | D32: 0 | E32: 0 | F32: 40000 | G32: 5000 | H32: 2000 | I32: 8000 | J32: =(1-$D32)*E32 -> 0 | K32: =(1-$D32)*F32 -> 40000 | L32: =G32 -> 5000 | M32: =(1-$D32)*H32 -> 2000 | N32: =(1-$D32)*I32 -> 8000 | O32: 11880 | P32: =14330-5700 -> 8630 | Q32: 0 | R32: 0 | S32: 0 | T32: 0 | U32: 0 | V32: 0 | W32: 0 | X32: 0 | Y32: 0 | Z32: =SUM(J32:Y32) -> 75510 | AA32: 40000 | AB32: =Z32-AA32 -> 35510 | AC32: =IF(AND($T32=6000, ($T32+$W32-$AB32)>=6000),T32,"") | AD32: =IF(AND($T32=8000, ($T32+$W32-$AB32)>=8000),T32,"") | AE32: =IF(($T32+$W32-$AB32)>=$T32+8000,W32,"")
A33: ADIGUN | B33: AHNAF ARAOLA | C33: PLAYGROUP 1 | D33: 0.05 | E33: 0 | F33: 26000 | G33: 4000 | H33: 1000 | I33: 0 | J33: =(1-$D33)*E33 -> 0 | K33: =(1-$D33)*F33 -> 24700 | L33: =G33 -> 4000 | M33: =(1-$D33)*H33 -> 950 | N33: =(1-$D33)*I33 -> 0 | O33: 6840 | P33: 5300 | Q33: 0 | R33: 0 | S33: 0 | T33: 0 | U33: 0 | V33: 0 | W33: 0 | X33: 0 | Y33: 0 | Z33: =SUM(J33:Y33) -> 41790 | AA33: 43140 | AB33: =Z33-AA33 -> -1350 | AC33: =IF(AND($T33=6000, ($T33+$W33-$AB33)>=6000),T33,"") | AD33: =IF(AND($T33=8000, ($T33+$W33-$AB33)>=8000),T33,"") | AE33: =IF(($T33+$W33-$AB33)>=$T33+8000,W33,"") | AF33: BONUS
A34: AGUNBIADE | B34: CHRISTIANAH OLUWAKEMI | C34: JUNIOR SECONDARY SCHOOL 1 | D34: 0 | E34: 3000 | F34: 33000 | G34: 5000 | H34: 2000 | I34: 6000 | J34: =(1-$D34)*E34 -> 3000 | K34: =(1-$D34)*F34 -> 33000 | L34: =G34 -> 5000 | M34: =(1-$D34)*H34 -> 2000 | N34: =(1-$D34)*I34 -> 6000 | O34: =19320-11160 -> 8160 | P34: 16190 | Q34: 12000 | R34: 8000 | S34: 8000 | T34: 8000 | U34: 0 | V34: 0 | W34: 0 | X34: 0 | Y34: 0 | Z34: =SUM(J34:Y34) -> 109350 | AA34: 60000 | AB34: =Z34-AA34 -> 49350 | AC34: =IF(AND($T34=6000, ($T34+$W34-$AB34)>=6000),T34,"") | AD34: =IF(AND($T34=8000, ($T34+$W34-$AB34)>=8000),T34,"") | AE34: =IF(($T34+$W34-$AB34)>=$T34+8000,W34,"")
A35: AKANDE | B35: MICHELLE OREOFE | C35: CRECHE | D35: 0.25 | E35: 0 | F35: 26000 | G35: 2000 | H35: 0 | I35: 0 | J35: =(1-$D35)*E35 -> 0 | K35: =(1-$D35)*F35 -> 19500 | L35: =G35 -> 2000 | M35: =(1-$D35)*H35 -> 0 | N35: =(1-$D35)*I35 -> 0 | O35: 0 | P35: 3050 | Q35: 0 | R35: 0 | S35: 0 | T35: 0 | U35: 0 | V35: 0 | W35: 0 | X35: 0 | Y35: 0 | Z35: =SUM(J35:Y35) -> 24550 | AA35: 11300 | AB35: =Z35-AA35 -> 13250 | AC35: =IF(AND($T35=6000, ($T35+$W35-$AB35)>=6000),T35,"") | AD35: =IF(AND($T35=8000, ($T35+$W35-$AB35)>=8000),T35,"") | AE35: =IF(($T35+$W35-$AB35)>=$T35+8000,W35,"")
A36: AKANDE | B36: ZION AYANFE | C36: NURSERY 1 | D36: 0.3 | E36: 0 | F36: 26000 | G36: 4000 | H36: 0 | I36: 0 | J36: =(1-$D36)*E36 -> 0 | K36: =(1-$D36)*F36 -> 18200 | L36: =G36 -> 4000 | M36: =(1-$D36)*H36 -> 0 | N36: =(1-$D36)*I36 -> 0 | O36: 13380 | P36: 7550 | Q36: 0 | R36: 0 | S36: 0 | T36: 6000 | U36: 0 | V36: 0 | W36: 0 | X36: 0 | Y36: 0 | Z36: =SUM(J36:Y36) -> 49130 | AA36: 49130 | AB36: =Z36-AA36 -> 0 | AC36: =IF(AND($T36=6000, ($T36+$W36-$AB36)>=6000),T36,"") -> 6000 | AD36: =IF(AND($T36=8000, ($T36+$W36-$AB36)>=8000),T36,"") | AE36: =IF(($T36+$W36-$AB36)>=$T36+8000,W36,"") | AF36: BONUS
A37: AKINBOSOYE | B37: DEBORAH OLUWADARA | C37: NURSERY 2 | D37: 0.25 | E37: 0 | F37: 26000 | G37: 4000 | H37: 0 | I37: 0 | J37: =(1-$D37)*E37 -> 0 | K37: =(1-$D37)*F37 -> 19500 | L37: =G37 -> 4000 | M37: =(1-$D37)*H37 -> 0 | N37: =(1-$D37)*I37 -> 0 | O37: 24930 | P37: 10730 | Q37: 0 | R37: 0 | S37: 0 | T37: 6000 | U37: 0 | V37: 0 | W37: 0 | X37: 0 | Y37: 0 | Z37: =SUM(J37:Y37) -> 65160 | AA37: 35000 | AB37: =Z37-AA37 -> 30160 | AC37: =IF(AND($T37=6000, ($T37+$W37-$AB37)>=6000),T37,"") | AD37: =IF(AND($T37=8000, ($T37+$W37-$AB37)>=8000),T37,"") | AE37: =IF(($T37+$W37-$AB37)>=$T37+8000,W37,"")
A38: AKINBOSOYE | B38: DANIEL IYANUOLUWA | C38: PRIMARY 2 | D38: 0.25 | E38: 0 | F38: 28000 | G38: 4000 | H38: 0 | I38: 5000 | J38: =(1-$D38)*E38 -> 0 | K38: =(1-$D38)*F38 -> 21000 | L38: =G38 -> 4000 | M38: =(1-$D38)*H38 -> 0 | N38: =(1-$D38)*I38 -> 3750 | O38: 26150 | P38: 11330 | Q38: 0 | R38: 0 | S38: 0 | T38: 6000 | U38: 0 | V38: 0 | W38: 0 | X38: 0 | Y38: 250 | Z38: =SUM(J38:Y38) -> 72480 | AA38: 35000 | AB38: =Z38-AA38 -> 37480 | AC38: =IF(AND($T38=6000, ($T38+$W38-$AB38)>=6000),T38,"") | AD38: =IF(AND($T38=8000, ($T38+$W38-$AB38)>=8000),T38,"") | AE38: =IF(($T38+$W38-$AB38)>=$T38+8000,W38,"")
A39: AKINDURO | B39: GABRIELLA OLUWAFIREWAMIRI | C39: PLAYGROUP 1 | D39: 0 | E39: 0 | F39: 26000 | G39: 4000 | H39: 1000 | I39: 0 | J39: =(1-$D39)*E39 -> 0 | K39: =(1-$D39)*F39 -> 26000 | L39: =G39 -> 4000 | M39: =(1-$D39)*H39 -> 1000 | N39: =(1-$D39)*I39 -> 0 | O39: 6840 | P39: 5300 | Q39: 0 | R39: 0 | S39: 0 | T39: 0 | U39: 0 | V39: 0 | W39: 0 | X39: 0 | Y39: 0 | Z39: =SUM(J39:Y39) -> 43140 | AA39: 43140 | AB39: =Z39-AA39 -> 0 | AC39: =IF(AND($T39=6000, ($T39+$W39-$AB39)>=6000),T39,"") | AD39: =IF(AND($T39=8000, ($T39+$W39-$AB39)>=8000),T39,"") | AE39: =IF(($T39+$W39-$AB39)>=$T39+8000,W39,"")
A40: AKINYEMI | B40: DANIEL | C40: NURSERY 1 | D40: 0 | E40: 0 | F40: 26000 | G40: 4000 | H40: 0 | I40: 0 | J40: =(1-$D40)*E40 -> 0 | K40: =(1-$D40)*F40 -> 26000 | L40: =G40 -> 4000 | M40: =(1-$D40)*H40 -> 0 | N40: =(1-$D40)*I40 -> 0 | O40: 13380 | P40: 7550 | Q40: 0 | R40: 0 | S40: 0 | T40: 6000 | U40: 0 | V40: 0 | W40: 0 | X40: 0 | Y40: 0 | Z40: =SUM(J40:Y40) -> 56930 | AA40: 56930 | AB40: =Z40-AA40 -> 0 | AC40: =IF(AND($T40=6000, ($T40+$W40-$AB40)>=6000),T40,"") -> 6000 | AD40: =IF(AND($T40=8000, ($T40+$W40-$AB40)>=8000),T40,"") | AE40: =IF(($T40+$W40-$AB40)>=$T40+8000,W40,"")
...

Sheet 1ST TERM PAY LOG
A1: DATE | B1: BANK | C1: NARRATION | D1: CREDIT | E1: STUDENT | F1: =SUMIF(E1:E1000, "<>", D1:D1000) -> 5264265
A2: 46278 | B2: WEMA | C2: NIP:AYOBAMI KASALI | D2: 60000 | E2: ABDULAZEEZ FAMILY
A3: 46306 | B3: WEMA | C3: AYOBAMI KASALI - Abdulazeez Abdullah Balance | D3: 21180 | E3: ABDULAZEEZ FAMILY
A4: 46300 | B4: WEMA | C4: NIP:SAIDI ABIOLA LATEEF | D4: 40000 | E4: ABDULLATEEF MUHAMMED
A5: 46277 | B5: WEMA | C5: NIP:JOHN ABIODUN SAMSON | D5: 30000 | E5: ABIODUN DANIEL
A6: 46265 | B6: WEMA | C6: NIP:ABIMBOLA ADENIKE ALABI | D6: 60000 | E6: ABIODUN FAMILY
A7: 46280 | B7: WEMA | C7: NIP:MARIAM WURAOLA ABIDOLA | D7: 40000 | E7: ADEBOWALE MARTIN
A8: 46282 | B8: WEMA | C8: NIP:MARIAM WURAOLA ABIDOLA | D8: 50000 | E8: ADEBOWALE MARTIN
A9: 46286 | B9: WEMA | C9: NIP:MARIAM WURAOLA ABIDOLA | D9: 29000 | E9: ADEBOWALE MARTIN
A10: 46286 | B10: WEMA | C10: NIP:EBENEZER OLALEKAN ADEBOYE | D10: 50000 | E10: ADEBOYE FAMILY
A11: 46299 | B11: WEMA | C11: NIP:EBENEZER OLALEKAN ADEBOYE | D11: 20000 | E11: ADEBOYE FAMILY
A12: 46268 | B12: WEMA | C12: NIP:SUKURA DASOLA MUKAILA | D12: 42140 | E12: ADEDAMOLA IREMIDE
A13: 46280 | B13: WEMA | C13: NIP:TUNDE ADEGOKE OJO | D13: 80000 | E13: ADEDAYO FAMILY
... A116: 46290 | B116: WEMA | C116: NIP:FATIMO OMOLABAKE ADEYEMO | D116: 16880 | E116: WAHAB FAIZA
A117: 46279 | B117: MONIEPOINT | C117: damilola oluwapeju samuel | D117: 20180
A118: 46304 | B118: WEMA | C118: NIP:JOHN ABIODUN SAMSON | D118: 20200
A119: 46307 | B119: WEMA | C119: NIP:SAHEED ADEKUNLE ADEBUNMI | D119: 113750 | E119: ADEBUNMI FAMILY

Sheet 1ST TERM REMIT
B1: PRIMARY LESSON | C1: TOTAL AMOUNT TO REMIT (70%) | D1: AMOUNT REMITTED | E1: DATE REMITTED | F1: CURRENT BALANCE
A2: AMOUNT RECEIVED | B2: ='1ST TERM ACCOUNT'!AC137 -> 78000 | C2: =B2*0.7 -> 54600 | F2: =$C$2-D2 -> 54600
A3: TOTAL EXPECTED AMOUNT | B3: =SUMIF('1ST TERM ACCOUNT'!T13:T136,6000) -> 216000 | F3: =$C$2-(D2+D3) -> 54600
A4: EXPECTED BALANCE | B4: =B3-B2 -> 138000 | F4: =$C$2-(D2+D3+D4) -> 54600
F5: =$C$2-(D2+D3+D4+D5) -> 54600
B7: SECONDARY LESSON | C7: TOTAL AMOUNT TO REMIT (70%) | D7: AMOUNT REMITTED | E7: DATE REMITTED | F7: CURRENT BALANCE
A8: AMOUNT RECEIVED | B8: ='1ST TERM ACCOUNT'!AD137 -> 0 | C8: =B8*0.7 -> 0 | F8: =$C$8-D8 -> 0
A9: TOTAL EXPECTED AMOUNT | B9: =SUMIF('1ST TERM ACCOUNT'!T13:T136,8000) -> 32000 | F9: =$C$8-(D8+D9) -> 0
A10: EXPECTED BALANCE | B10: =B9-B8 -> 32000 | F10: =$C$8-(D8+D9+D10) -> 0
F11: =$C$8-(D8+D9+D10+D11) -> 0
B13: PARTY DUES | C13: TOTAL AMOUNT TO REMIT (100%) | D13: AMOUNT REMITTED | E13: DATE REMITTED | F13: CURRENT BALANCE
A14: AMOUNT RECEIVED | B14: ='1ST TERM ACCOUNT'!AE137 -> 0 | C14: =B14 -> 0 | F14: =$C$14-D14 -> 0
A15: TOTAL EXPECTED AMOUNT | B15: =SUM('1ST TERM ACCOUNT'!W13:W136) -> 0 | F15: =$C$14-(D14+D15) -> 0
A16: EXPECTED BALANCE | B16: =B15-B14 -> 0 | F16: =$C$14-(D14+D15+D16) -> 0
F17: =$C$14-(D14+D15+D16+D17) -> 0
F18: =$C$14-(D15+D16+D17+D18+D14) -> 0
F19: =$C$14-(D14+D15+D16+D17+D18+D19) -> 0
